2023-10-10 23:28
Tags: #leetcode
## Description

Нужно написать функцию, которая на вход принимает функцию `fn` и время `t` в миллисекундах. Возвращает ограниченную по времени версию входной функции (`TLFunction`). `fn` принимает аргументы и прокидывает их `TLFunction`.

`TLFunction` функция следует правилам ниже:
1. Если функция `fn` завершится в пределах срока `t`, то `TLFunction` резолвится с этим результатом;
2. Если выполнение функции `fn` превышает ограничение по времени, то `TLFunction` реджектится со строкой `"Time Limit Exceeded"`.

**Example 1:**
>**Input:**
    `fn = async (n) => { 
		`await new Promise(res => setTimeout(res, 100));`
		 `return n * n;`
	 `}`
	`inputs = [5]`
	`t = 150`
>**Output:**  `{"resolved":25,"time":100}`

**Example 2:**
>**Input:**
    `fn = async (n) => { 
		`await new Promise(res => setTimeout(res, 100));`
		 `return n * n;`
	 `}`
	`inputs = [5]`
	`t = 50`
>**Output:**  `{"rejected":"Time Limit Exceeded","time":50}`

## Answers

### Answer 1

Это решение первое, что пришло в голову, и как-то образом оно прошло через тесты. Здесь вызывают вопросы много чего и `setInterval`, который каждую единицу времени проверяет не превышен ли лимит, и отслеживание времени исполнения функции с последующей его проверкой. 

```typescript
type Callback = (...params: any[]) => Promise<any>;

function timeLimit(callback: Callback, timeLimit: number): Callback {
  return function (...args) {
    const timeStart = Date.now();

    return new Promise((resolve, reject) => {
      const timerId = setInterval(() => {
        const timeEnd = Date.now() - timeStart;

        if (timeEnd > timeLimit) {
          clearInterval(timerId);
          reject('Time Limit Exceeded');
        }
      }, 10);

      callback(...args)
        .then(data => resolve(data))
        .catch((error) => reject(error));
    });
  };
}
```
### Answer 2

Данное решение уже поэлегантнее. Тут как и в предыдущем есть 2 `reject`, один нужен для генерации ошибки `'Time Limit Exceeded'`, а второй, чтобы обработать ошибку, которую может вернуть `callback`. Без `catch` приложение просто упадет, так как в конструкции `new Promise` нужно обработать ошибку.

```typescript
type Callback = (...params: any[]) => Promise<any>;

function timeLimit(callback: Callback, timeLimit: number): Callback {
  return function (...args) {
    return new Promise((resolve, reject) => {
      const timerId = setTimeout(() => {
          reject('Time Limit Exceeded');
      }, timeLimit);

      callback(...args)
        .then(data => resolve(data))
        .catch((error) => reject(error))
        .finally(() => clearTimeout(timeLimit));
    });
  };
}
```
### Answer 3

Лучшее решение и по чистоте кода и по задумке. Вернется первый промис, который выполнится, либо оригинальной с результатом или ошибкой, либо промис с сообщением `'Time Limit Exceeded'`.

```typescript
type Callback = (...params: any[]) => Promise<any>;

function timeLimit(callback: Callback, timeLimit: number): Callback {
  return function (...args) {
      const originalPromise = callback(...args);
      const timeoutPromise = new Promise((_, reject) => {
          setTimeout(() => {
              reject('Time Limit Exceeded');
          }, timeLimit);
      });

      return Promise.race([originalPromise, timeoutPromise]);
  };
}
```